Workbook

Sheet How to Use
A1: Redblock AI Studio - End-to-end Test Suite
A3: Scope | B3: Full product path: Agent setup -> asset upload -> video/doc-to-redflow generation -> editor & syntax -> execution by the Agent -> results review -> publish -> API trigger, plus security and performance.
A4: Sources | B4: Redblock docs (Agents, redflow Syntax Reference, Guide v3.0, May 2026) and console.dev screenshots from 30 Sep 2026.
A5: Sheets | B5: Summary: live counts per module. Test Cases: all cases. Test Assets: recordings/docs to prepare once and reuse. Open Questions: behaviour the docs don't define, and doc inconsistencies.
A7: Fill in (yellow cells) | B7: On Test Cases, fill Status (dropdown), Actual Result, Bug ID, Tester and Date Run. Everything else is the test definition.
A8: Example row | B8: Status: Fail | Actual Result: 'Agent clicked Profile Save instead of Roles Save; roles not saved' | Bug ID: RB-1432 | Tester: Heet | Date Run: 01-Oct-2026
A9: Status values | B9: Not Run (default), Pass, Fail, Blocked (can't run: env/data/feature missing), N/A (not applicable to this build).
A10: Priority | B10: P0 = must pass before any customer POC. P1 = core functionality. P2 = important edge cases. P3 = nice to have / cosmetic.
A11: Type | B11: Functional, Negative, Boundary, Edge, AI Quality (generation/agent accuracy), Robustness, Security, Performance, Integration.
A12: 'Record' in Expected | B12: Where the docs don't define behaviour, the Expected Result says 'Record ...'. Note what actually happens and raise it in Open Questions if it looks wrong.
A14: AI Quality metrics | B14: For every video-based case, log: steps in video, steps generated, steps missed, extra steps, and whether the redflow ran first time without edits. These give generation precision/recall and first-run success rate.
A15: Test Assets | B15: Record the assets on the Test Assets sheet once, against a stable test app (your SailPoint ISC demo tenant works). Keep a written step list for each so generated redflows can be compared step by step.
A16: Destructive tests | B16: Run Remove/Deactivate tests only against test users in a sandbox tenant. Stop Execution does not roll back completed actions.

Sheet Summary
A1: Redblock AI Studio - Test Suite Summary
A2: Counts update automatically as Status is filled in on the Test Cases sheet.
A4: Phase | B4: Module | C4: Total | D4: P0 | E4: P1 | F4: P2 | G4: P3 | H4: Pass | I4: Fail | J4: Blocked | K4: Not Run | L4: N/A | M4: Executed % | N4: Pass % of executed
A5: 1. Setup | B5: Agents List | C5: =COUNTIF('Test Cases'!$C$2:$C$446,B5) -> 9 | D5: =COUNTIFS('Test Cases'!$C$2:$C$446,B5,'Test Cases'!$J$2:$J$446,"P0") -> 0 | E5: =COUNTIFS('Test Cases'!$C$2:$C$446,B5,'Test Cases'!$J$2:$J$446,"P1") -> 2 | F5: =COUNTIFS('Test Cases'!$C$2:$C$446,B5,'Test Cases'!$J$2:$J$446,"P2") -> 5 | G5: =COUNTIFS('Test Cases'!$C$2:$C$446,B5,'Test Cases'!$J$2:$J$446,"P3") -> 2 | H5: =COUNTIFS('Test Cases'!$C$2:$C$446,B5,'Test Cases'!$L$2:$L$446,"Pass") -> 0 | I5: =COUNTIFS('Test Cases'!$C$2:$C$446,B5,'Test Cases'!$L$2:$L$446,"Fail") -> 0 | J5: =COUNTIFS('Test Cases'!$C$2:$C$446,B5,'Test Cases'!$L$2:$L$446,"Blocked") -> 0 | K5: =COUNTIFS('Test Cases'!$C$2:$C$446,B5,'Test Cases'!$L$2:$L$446,"Not Run") -> 9 | L5: =COUNTIFS('Test Cases'!$C$2:$C$446,B5,'Test Cases'!$L$2:$L$446,"N/A") -> 0 | M5: =IF(C5-L5=0,0,(H5+I5+J5)/(C5-L5)) -> 0 | N5: =IF(H5+I5=0,0,H5/(H5+I5)) -> 0
A6: 1. Setup | B6: Agent Profile | C6: =COUNTIF('Test Cases'!$C$2:$C$446,B6) -> 16 | D6: =COUNTIFS('Test Cases'!$C$2:$C$446,B6,'Test Cases'!$J$2:$J$446,"P0") -> 2 | E6: =COUNTIFS('Test Cases'!$C$2:$C$446,B6,'Test Cases'!$J$2:$J$446,"P1") -> 6 | F6: =COUNTIFS('Test Cases'!$C$2:$C$446,B6,'Test Cases'!$J$2:$J$446,"P2") -> 6 | G6: =COUNTIFS('Test Cases'!$C$2:$C$446,B6,'Test Cases'!$J$2:$J$446,"P3") -> 2 | H6: =COUNTIFS('Test Cases'!$C$2:$C$446,B6,'Test Cases'!$L$2:$L$446,"Pass") -> 0 | I6: =COUNTIFS('Test Cases'!$C$2:$C$446,B6,'Test Cases'!$L$2:$L$446,"Fail") -> 0 | J6: =COUNTIFS('Test Cases'!$C$2:$C$446,B6,'Test Cases'!$L$2:$L$446,"Blocked") -> 0 | K6: =COUNTIFS('Test Cases'!$C$2:$C$446,B6,'Test Cases'!$L$2:$L$446,"Not Run") -> 16 | L6: =COUNTIFS('Test Cases'!$C$2:$C$446,B6,'Test Cases'!$L$2:$L$446,"N/A") -> 0 | M6: =IF(C6-L6=0,0,(H6+I6+J6)/(C6-L6)) -> 0 | N6: =IF(H6+I6=0,0,H6/(H6+I6)) -> 0
A7: 1. Setup | B7: Agent Identity | C7: =COUNTIF('Test Cases'!$C$2:$C$446,B7) -> 32 | D7: =COUNTIFS('Test Cases'!$C$2:$C$446,B7,'Test Cases'!$J$2:$J$446,"P0") -> 7 | E7: =COUNTIFS('Test Cases'!$C$2:$C$446,B7,'Test Cases'!$J$2:$J$446,"P1") -> 13 | F7: =COUNTIFS('Test Cases'!$C$2:$C$446,B7,'Test Cases'!$J$2:$J$446,"P2") -> 11 | G7: =COUNTIFS('Test Cases'!$C$2:$C$446,B7,'Test Cases'!$J$2:$J$446,"P3") -> 1 | H7: =COUNTIFS('Test Cases'!$C$2:$C$446,B7,'Test Cases'!$L$2:$L$446,"Pass") -> 0 | I7: =COUNTIFS('Test Cases'!$C$2:$C$446,B7,'Test Cases'!$L$2:$L$446,"Fail") -> 0 | J7: =COUNTIFS('Test Cases'!$C$2:$C$446,B7,'Test Cases'!$L$2:$L$446,"Blocked") -> 0 | K7: =COUNTIFS('Test Cases'!$C$2:$C$446,B7,'Test Cases'!$L$2:$L$446,"Not Run") -> 32 | L7: =COUNTIFS('Test Cases'!$C$2:$C$446,B7,'Test Cases'!$L$2:$L$446,"N/A") -> 0 | M7: =IF(C7-L7=0,0,(H7+I7+J7)/(C7-L7)) -> 0 | N7: =IF(H7+I7=0,0,H7/(H7+I7)) -> 0
A8: 1. Setup | B8: Skills Tab | C8: =COUNTIF('Test Cases'!$C$2:$C$446,B8) -> 10 | D8: =COUNTIFS('Test Cases'!$C$2:$C$446,B8,'Test Cases'!$J$2:$J$446,"P0") -> 0 | E8: =COUNTIFS('Test Cases'!$C$2:$C$446,B8,'Test Cases'!$J$2:$J$446,"P1") -> 3 | F8: =COUNTIFS('Test Cases'!$C$2:$C$446,B8,'Test Cases'!$J$2:$J$446,"P2") -> 5 | G8: =COUNTIFS('Test Cases'!$C$2:$C$446,B8,'Test Cases'!$J$2:$J$446,"P3") -> 2 | H8: =COUNTIFS('Test Cases'!$C$2:$C$446,B8,'Test Cases'!$L$2:$L$446,"Pass") -> 0 | I8: =COUNTIFS('Test Cases'!$C$2:$C$446,B8,'Test Cases'!$L$2:$L$446,"Fail") -> 0 | J8: =COUNTIFS('Test Cases'!$C$2:$C$446,B8,'Test Cases'!$L$2:$L$446,"Blocked") -> 0 | K8: =COUNTIFS('Test Cases'!$C$2:$C$446,B8,'Test Cases'!$L$2:$L$446,"Not Run") -> 10 | L8: =COUNTIFS('Test Cases'!$C$2:$C$446,B8,'Test Cases'!$L$2:$L$446,"N/A") -> 0 | M8: =IF(C8-L8=0,0,(H8+I8+J8)/(C8-L8)) -> 0 | N8: =IF(H8+I8=0,0,H8/(H8+I8)) -> 0
A9: 1. Setup | B9: Agent Settings | C9: =COUNTIF('Test Cases'!$C$2:$C$446,B9) -> 14 | D9: =COUNTIFS('Test Cases'!$C$2:$C$446,B9,'Test Cases'!$J$2:$J$446,"P0") -> 1 | E9: =COUNTIFS('Test Cases'!$C$2:$C$446,B9,'Test Cases'!$J$2:$J$446,"P1") -> 4 | F9: =COUNTIFS('Test Cases'!$C$2:$C$446,B9,'Test Cases'!$J$2:$J$446,"P2") -> 7 | G9: =COUNTIFS('Test Cases'!$C$2:$C$446,B9,'Test Cases'!$J$2:$J$446,"P3") -> 2 | H9: =COUNTIFS('Test Cases'!$C$2:$C$446,B9,'Test Cases'!$L$2:$L$446,"Pass") -> 0 | I9: =COUNTIFS('Test Cases'!$C$2:$C$446,B9,'Test Cases'!$L$2:$L$446,"Fail") -> 0 | J9: =COUNTIFS('Test Cases'!$C$2:$C$446,B9,'Test Cases'!$L$2:$L$446,"Blocked") -> 0 | K9: =COUNTIFS('Test Cases'!$C$2:$C$446,B9,'Test Cases'!$L$2:$L$446,"Not Run") -> 14 | L9: =COUNTIFS('Test Cases'!$C$2:$C$446,B9,'Test Cases'!$L$2:$L$446,"N/A") -> 0 | M9: =IF(C9-L9=0,0,(H9+I9+J9)/(C9-L9)) -> 0 | N9: =IF(H9+I9=0,0,H9/(H9+I9)) -> 0
A10: 1. Setup | B10: Certified Agents | C10: =COUNTIF('Test Cases'!$C$2:$C$446,B10) -> 4 | D10: =COUNTIFS('Test Cases'!$C$2:$C$446,B10,'Test Cases'!$J$2:$J$446,"P0") -> 0 | E10: =COUNTIFS('Test Cases'!$C$2:$C$446,B10,'Test Cases'!$J$2:$J$446,"P1") -> 2 | F10: =COUNTIFS('Test Cases'!$C$2:$C$446,B10,'Test Cases'!$J$2:$J$446,"P2") -> 1 | G10: =COUNTIFS('Test Cases'!$C$2:$C$446,B10,'Test Cases'!$J$2:$J$446,"P3") -> 1 | H10: =COUNTIFS('Test Cases'!$C$2:$C$446,B10,'Test Cases'!$L$2:$L$446,"Pass") -> 0 | I10: =COUNTIFS('Test Cases'!$C$2:$C$446,B10,'Test Cases'!$L$2:$L$446,"Fail") -> 0 | J10: =COUNTIFS('Test Cases'!$C$2:$C$446,B10,'Test Cases'!$L$2:$L$446,"Blocked") -> 0 | K10: =COUNTIFS('Test Cases'!$C$2:$C$446,B10,'Test Cases'!$L$2:$L$446,"Not Run") -> 4 | L10: =COUNTIFS('Test Cases'!$C$2:$C$446,B10,'Test Cases'!$L$2:$L$446,"N/A") -> 0 | M10: =IF(C10-L10=0,0,(H10+I10+J10)/(C10-L10)) -> 0 | N10: =IF(H10+I10=0,0,H10/(H10+I10)) -> 0
A11: 2. redflow creation | B11: Asset Upload | C11: =COUNTIF('Test Cases'!$C$2:$C$446,B11) -> 34 | D11: =COUNTIFS('Test Cases'!$C$2:$C$446,B11,'Test Cases'!$J$2:$J$446,"P0") -> 2 | E11: =COUNTIFS('Test Cases'!$C$2:$C$446,B11,'Test Cases'!$J$2:$J$446,"P1") -> 16 | F11: =COUNTIFS('Test Cases'!$C$2:$C$446,B11,'Test Cases'!$J$2:$J$446,"P2") -> 10 | G11: =COUNTIFS('Test Cases'!$C$2:$C$446,B11,'Test Cases'!$J$2:$J$446,"P3") -> 6 | H11: =COUNTIFS('Test Cases'!$C$2:$C$446,B11,'Test Cases'!$L$2:$L$446,"Pass") -> 0 | I11: =COUNTIFS('Test Cases'!$C$2:$C$446,B11,'Test Cases'!$L$2:$L$446,"Fail") -> 0 | J11: =COUNTIFS('Test Cases'!$C$2:$C$446,B11,'Test Cases'!$L$2:$L$446,"Blocked") -> 0 | K11: =COUNTIFS('Test Cases'!$C$2:$C$446,B11,'Test Cases'!$L$2:$L$446,"Not Run") -> 34 | L11: =COUNTIFS('Test Cases'!$C$2:$C$446,B11,'Test Cases'!$L$2:$L$446,"N/A") -> 0 | M11: =IF(C11-L11=0,0,(H11+I11+J11)/(C11-L11)) -> 0 | N11: =IF(H11+I11=0,0,H11/(H11+I11)) -> 0
A12: 2. redflow creation | B12: Generation Lifecycle | C12: =COUNTIF('Test Cases'!$C$2:$C$446,B12) -> 13 | D12: =COUNTIFS('Test Cases'!$C$2:$C$446,B12,'Test Cases'!$J$2:$J$446,"P0") -> 1 | E12: =COUNTIFS('Test Cases'!$C$2:$C$446,B12,'Test Cases'!$J$2:$J$446,"P1") -> 8 | F12: =COUNTIFS('Test Cases'!$C$2:$C$446,B12,'Test Cases'!$J$2:$J$446,"P2") -> 4 | G12: =COUNTIFS('Test Cases'!$C$2:$C$446,B12,'Test Cases'!$J$2:$J$446,"P3") -> 0 | H12: =COUNTIFS('Test Cases'!$C$2:$C$446,B12,'Test Cases'!$L$2:$L$446,"Pass") -> 0 | I12: =COUNTIFS('Test Cases'!$C$2:$C$446,B12,'Test Cases'!$L$2:$L$446,"Fail") -> 0 | J12: =COUNTIFS('Test Cases'!$C$2:$C$446,B12,'Test Cases'!$L$2:$L$446,"Blocked") -> 0 | K12: =COUNTIFS('Test Cases'!$C$2:$C$446,B12,'Test Cases'!$L$2:$L$446,"Not Run") -> 13 | L12: =COUNTIFS('Test Cases'!$C$2:$C$446,B12,'Test Cases'!$L$2:$L$446,"N/A") -> 0 | M12: =IF(C12-L12=0,0,(H12+I12+J12)/(C12-L12)) -> 0 | N12: =IF(H12+I12=0,0,H12/(H12+I12)) -> 0
A13: 2. redflow creation | B13: Generation Quality - Actions | C13: =COUNTIF('Test Cases'!$C$2:$C$446,B13) -> 54 | D13: =COUNTIFS('Test Cases'!$C$2:$C$446,B13,'Test Cases'!$J$2:$J$446,"P0") -> 15 | E13: =COUNTIFS('Test Cases'!$C$2:$C$446,B13,'Test Cases'!$J$2:$J$446,"P1") -> 24 | F13: =COUNTIFS('Test Cases'!$C$2:$C$446,B13,'Test Cases'!$J$2:$J$446,"P2") -> 14 | G13: =COUNTIFS('Test Cases'!$C$2:$C$446,B13,'Test Cases'!$J$2:$J$446,"P3") -> 1 | H13: =COUNTIFS('Test Cases'!$C$2:$C$446,B13,'Test Cases'!$L$2:$L$446,"Pass") -> 0 | I13: =COUNTIFS('Test Cases'!$C$2:$C$446,B13,'Test Cases'!$L$2:$L$446,"Fail") -> 0 | J13: =COUNTIFS('Test Cases'!$C$2:$C$446,B13,'Test Cases'!$L$2:$L$446,"Blocked") -> 0 | K13: =COUNTIFS('Test Cases'!$C$2:$C$446,B13,'Test Cases'!$L$2:$L$446,"Not Run") -> 54 | L13: =COUNTIFS('Test Cases'!$C$2:$C$446,B13,'Test Cases'!$L$2:$L$446,"N/A") -> 0 | M13: =IF(C13-L13=0,0,(H13+I13+J13)/(C13-L13)) -> 0 | N13: =IF(H13+I13=0,0,H13/(H13+I13)) -> 0
A14: 2. redflow creation | B14: Generation Quality - Docs & Instructions | C14: =COUNTIF('Test Cases'!$C$2:$C$446,B14) -> 11 | D14: =COUNTIFS('Test Cases'!$C$2:$C$446,B14,'Test Cases'!$J$2:$J$446,"P0") -> 1 | E14: =COUNTIFS('Test Cases'!$C$2:$C$446,B14,'Test Cases'!$J$2:$J$446,"P1") -> 4 | F14: =COUNTIFS('Test Cases'!$C$2:$C$446,B14,'Test Cases'!$J$2:$J$446,"P2") -> 4 | G14: =COUNTIFS('Test Cases'!$C$2:$C$446,B14,'Test Cases'!$J$2:$J$446,"P3") -> 2 | H14: =COUNTIFS('Test Cases'!$C$2:$C$446,B14,'Test Cases'!$L$2:$L$446,"Pass") -> 0 | I14: =COUNTIFS('Test Cases'!$C$2:$C$446,B14,'Test Cases'!$L$2:$L$446,"Fail") -> 0 | J14: =COUNTIFS('Test Cases'!$C$2:$C$446,B14,'Test Cases'!$L$2:$L$446,"Blocked") -> 0 | K14: =COUNTIFS('Test Cases'!$C$2:$C$446,B14,'Test Cases'!$L$2:$L$446,"Not Run") -> 11 | L14: =COUNTIFS('Test Cases'!$C$2:$C$446,B14,'Test Cases'!$L$2:$L$446,"N/A") -> 0 | M14: =IF(C14-L14=0,0,(H14+I14+J14)/(C14-L14)) -> 0 | N14: =IF(H14+I14=0,0,H14/(H14+I14)) -> 0
A15: 2. redflow creation | B15: Generation Quality - Aggregation | C15: =COUNTIF('Test Cases'!$C$2:$C$446,B15) -> 8 | D15: =COUNTIFS('Test Cases'!$C$2:$C$446,B15,'Test Cases'!$J$2:$J$446,"P0") -> 4 | E15: =COUNTIFS('Test Cases'!$C$2:$C$446,B15,'Test Cases'!$J$2:$J$446,"P1") -> 2 | F15: =COUNTIFS('Test Cases'!$C$2:$C$446,B15,'Test Cases'!$J$2:$J$446,"P2") -> 2 | G15: =COUNTIFS('Test Cases'!$C$2:$C$446,B15,'Test Cases'!$J$2:$J$446,"P3") -> 0 | H15: =COUNTIFS('Test Cases'!$C$2:$C$446,B15,'Test Cases'!$L$2:$L$446,"Pass") -> 0 | I15: =COUNTIFS('Test Cases'!$C$2:$C$446,B15,'Test Cases'!$L$2:$L$446,"Fail") -> 0 | J15: =COUNTIFS('Test Cases'!$C$2:$C$446,B15,'Test Cases'!$L$2:$L$446,"Blocked") -> 0 | K15: =COUNTIFS('Test Cases'!$C$2:$C$446,B15,'Test Cases'!$L$2:$L$446,"Not Run") -> 8 | L15: =COUNTIFS('Test Cases'!$C$2:$C$446,B15,'Test Cases'!$L$2:$L$446,"N/A") -> 0 | M15: =IF(C15-L15=0,0,(H15+I15+J15)/(C15-L15)) -> 0 | N15: =IF(H15+I15=0,0,H15/(H15+I15)) -> 0
A16: 2. redflow creation | B16: Select Existing redflow | C16: =COUNTIF('Test Cases'!$C$2:$C$446,B16) -> 12 | D16: =COUNTIFS('Test Cases'!$C$2:$C$446,B16,'Test Cases'!$J$2:$J$446,"P0") -> 1 | E16: =COUNTIFS('Test Cases'!$C$2:$C$446,B16,'Test Cases'!$J$2:$J$446,"P1") -> 6 | F16: =COUNTIFS('Test Cases'!$C$2:$C$446,B16,'Test Cases'!$J$2:$J$446,"P2") -> 3 | G16: =COUNTIFS('Test Cases'!$C$2:$C$446,B16,'Test Cases'!$J$2:$J$446,"P3") -> 2 | H16: =COUNTIFS('Test Cases'!$C$2:$C$446,B16,'Test Cases'!$L$2:$L$446,"Pass") -> 0 | I16: =COUNTIFS('Test Cases'!$C$2:$C$446,B16,'Test Cases'!$L$2:$L$446,"Fail") -> 0 | J16: =COUNTIFS('Test Cases'!$C$2:$C$446,B16,'Test Cases'!$L$2:$L$446,"Blocked") -> 0 | K16: =COUNTIFS('Test Cases'!$C$2:$C$446,B16,'Test Cases'!$L$2:$L$446,"Not Run") -> 12 | L16: =COUNTIFS('Test Cases'!$C$2:$C$446,B16,'Test Cases'!$L$2:$L$446,"N/A") -> 0 | M16: =IF(C16-L16=0,0,(H16+I16+J16)/(C16-L16)) -> 0 | N16: =IF(H16+I16=0,0,H16/(H16+I16)) -> 0
... A29: 4. Go-live | B29: Performance & Reliability | C29: =COUNTIF('Test Cases'!$C$2:$C$446,B29) -> 5 | D29: =COUNTIFS('Test Cases'!$C$2:$C$446,B29,'Test Cases'!$J$2:$J$446,"P0") -> 1 | E29: =COUNTIFS('Test Cases'!$C$2:$C$446,B29,'Test Cases'!$J$2:$J$446,"P1") -> 0 | F29: =COUNTIFS('Test Cases'!$C$2:$C$446,B29,'Test Cases'!$J$2:$J$446,"P2") -> 3 | G29: =COUNTIFS('Test Cases'!$C$2:$C$446,B29,'Test Cases'!$J$2:$J$446,"P3") -> 1 | H29: =COUNTIFS('Test Cases'!$C$2:$C$446,B29,'Test Cases'!$L$2:$L$446,"Pass") -> 0 | I29: =COUNTIFS('Test Cases'!$C$2:$C$446,B29,'Test Cases'!$L$2:$L$446,"Fail") -> 0 | J29: =COUNTIFS('Test Cases'!$C$2:$C$446,B29,'Test Cases'!$L$2:$L$446,"Blocked") -> 0 | K29: =COUNTIFS('Test Cases'!$C$2:$C$446,B29,'Test Cases'!$L$2:$L$446,"Not Run") -> 5 | L29: =COUNTIFS('Test Cases'!$C$2:$C$446,B29,'Test Cases'!$L$2:$L$446,"N/A") -> 0 | M29: =IF(C29-L29=0,0,(H29+I29+J29)/(C29-L29)) -> 0 | N29: =IF(H29+I29=0,0,H29/(H29+I29)) -> 0
A30: TOTAL | C30: =SUM(C5:C29) -> 445 | D30: =SUM(D5:D29) -> 86 | E30: =SUM(E5:E29) -> 187 | F30: =SUM(F5:F29) -> 132 | G30: =SUM(G5:G29) -> 40 | H30: =SUM(H5:H29) -> 0 | I30: =SUM(I5:I29) -> 0 | J30: =SUM(J5:J29) -> 0 | ... L30: =SUM(L5:L29) -> 0 | M30: =IF(C30-L30=0,0,(H30+I30+J30)/(C30-L30)) -> 0 | N30: =IF(H30+I30=0,0,H30/(H30+I30)) -> 0

Sheet Test Cases
A1: TC ID | B1: Phase | C1: Module | D1: Sub-area | E1: Test Scenario | F1: Preconditions | G1: Test Steps | H1: Test Data / Asset | I1: Expected Result | J1: Priority | K1: Type | L1: Status | M1: Actual Result | N1: Bug ID | O1: Tester | P1: Date Run | Q1: Notes
A2: AGL-001 | B2: 1. Setup | C2: Agents List | D2: Fleet view | E2: Agents list shows all columns | F2: At least 3 Agents exist in different states | G2: 1. Open AI Studio > Agents | H2: - | I2: Columns shown: Agent Name (with agt- ID), Authentication Status, Active Skills, Tags, Last Updated, Purpose, Actions. | J2: P2 | K2: Functional | L2: Not Run
A3: AGL-002 | B3: 1. Setup | C3: Agents List | D3: Fleet view | E3: Agent ID copy button copies the full agt- ID | F3: Agent exists | G3: 1. Open Agents list 2. Click copy icon under an Agent name 3. Paste into a text editor | H3: - | I3: Clipboard holds the complete agt-<uuid>; matches the ID in the Agent URL. | J3: P2 | K3: Functional | L3: Not Run
A4: AGL-003 | B4: 1. Setup | C4: Agents List | D4: Status | E4: Authentication Status shows all four states correctly | F4: Agents with: no credentials; valid creds; wrong password; check running | G4: 1. Open Agents list 2. Compare each Agent's status badge | H4: - | I4: Not Provided (grey), Valid (green), Invalid (red), In Progress (blue) shown for the matching Agents. | J4: P1 | K4: Functional | L4: Not Run
A5: AGL-004 | B5: 1. Setup | C5: Agents List | D5: Search | E5: Search by Agent name (full, partial, case-insensitive) | F5: Agents named 'Github BOA 2', 'Atlassian BOA dev' | G5: 1. Search 'github' 2. Search 'BOA' 3. Search 'GITHUB boa' 4. Search 'zzz-no-match' | H5: - | I5: Matching Agents only; partial and case-insensitive matches work; clear empty state for no results. | J5: P2 | K5: Functional | L5: Not Run
A6: AGL-005 | B6: 1. Setup | C6: Agents List | D6: Search | E6: Search with special characters does not break the page | F6: - | G6: 1. Search each value in the data column | H6: %, _, ', ", <script>, \, emoji | I6: No error, no script execution, no unfiltered list; empty state or correct matches. | J6: P2 | K6: Negative | L6: Not Run
A7: AGL-006 | B7: 1. Setup | C7: Agents List | D7: Filter | E7: Filter by Authentication Status and by Tags, combined with search | F7: Agents with mixed statuses and tags | G7: 1. Filter Status = Valid 2. Add Tag = prod 3. Type a search term 4. Clear filters | H7: - | I7: Results satisfy all active filters; clearing restores the full list. | J7: P2 | K7: Functional | L7: Not Run
A8: AGL-007 | B8: 1. Setup | C8: Agents List | D8: Pagination | E8: Pagination with many Agents | F8: > 1 page of Agents (e.g., 30+) | G8: 1. Page forward/back 2. Change page size if available 3. Apply a filter while on page 2 | H8: - | I8: No duplicates or missing rows across pages; filtering resets to page 1. | J8: P3 | K8: Functional | L8: Not Run
A9: AGL-008 | B9: 1. Setup | C9: Agents List | D9: Active Skills | E9: Active Skills column reflects only published Skills | F9: Agent with 1 published and 1 Pending Skill | G9: 1. Open Agents list 2. Check Active Skills for that Agent | H9: - | I9: Only the published Skill is listed/counted. | J9: P1 | K9: Functional | L9: Not Run
A10: AGL-009 | B10: 1. Setup | C10: Agents List | D10: Last Updated | E10: Last Updated changes after profile/identity/skill edits | F10: Agent exists | G10: 1. Note Last Updated 2. Edit Agent Purpose and save 3. Return to list | H10: - | I10: Last Updated shows the new time in the user's timezone. | J10: P3 | K10: Functional | L10: Not Run
A11: AGP-001 | B11: 1. Setup | C11: Agent Profile | D11: Create entry | E11: + Create Agent offers Certified and Custom paths | F11: - | G11: 1. Click + Create Agent | H11: - | I11: Two options: Use Redblock Certified Agent, Build Custom Agent. | J11: P2 | K11: Functional | L11: Not Run
A12: AGP-002 | B12: 1. Setup | C12: Agent Profile | D12: Create | E12: Create custom Agent with valid Name, Purpose, Tags | F12: - | G12: 1. Build Custom Agent 2. Enter Name, Purpose, 2 tags 3. Click Create | H12: Name: 'QA Salesforce Sandbox', Purpose: 'QA JML testing', Tags: sandbox, qa | I12: Agent created with agt- ID; Authentication Status = Not Provided; appears in list; creation logged in Logs with user and timestamp. | J12: P0 | K12: Functional | L12: Not Run
A13: AGP-003 | B13: 1. Setup | C13: Agent Profile | D13: Validation | E13: Agent Name is required | F13: - | G13: 1. Leave Name empty, fill Purpose 2. Try to Create | H13: - | I13: Create blocked with a required-field message. | J13: P1 | K13: Negative | L13: Not Run
... A16: AGP-006 | B16: 1. Setup | C16: Agent Profile | D16: Validation | E16: Agent Name max length 64 (boundary) | F16: - | G16: 1. Enter 63, 64, then 65 characters 2. Try to Create each | H16: 63 / 64 / 65 char strings | I16: 63 and 64 accepted; 65 blocked or truncated with a clear message. | J16: P1 | K16: Boundary | L16: Not Run
A17: AGP-007 | B17: 1. Setup | C17: Agent Profile | D17: Validation | E17: Agent Name must be unique | F17: Agent 'QA Dup' exists | G17: 1. Create another Agent named 'QA Dup' 2. Repeat with 'qa dup' and ' QA Dup ' | H17: - | I17: Exact duplicate rejected. Case/whitespace variants: behaviour matches product decision (record it). | J17: P1 | K17: Negative | L17: Not Run | Q17: Confirm whether uniqueness is case-insensitive and trims spaces.
A18: AGP-008 | B18: 1. Setup | C18: Agent Profile | D18: Validation | E18: Special characters and unicode in Name/Purpose | F18: - | G18: 1. Create Agents using each value | H18: O'Brien App, App & Co, Zürich-HR, 日本語, emoji, <b>x</b> | I18: Saved and displayed exactly as typed; HTML not rendered; no broken layout. | J18: P2 | K18: Edge | L18: Not Run
A19: AGP-009 | B19: 1. Setup | C19: Agent Profile | D19: Immutability | E19: Agent Name cannot be changed after creation | F19: Agent exists | G19: 1. Open Agent Profile 2. Click Edit | H19: - | I19: Name field is read-only in edit mode; Purpose and Tags are editable. | J19: P0 | K19: Functional | L19: Not Run
A20: AGP-010 | B20: 1. Setup | C20: Agent Profile | D20: Edit | E20: Edit Purpose and Tags and save | F20: Agent exists | G20: 1. Click Edit 2. Change Purpose 3. Add and remove tags 4. Save | H20: - | I20: Changes persist after reload; Save disabled until something changes. | J20: P1 | K20: Functional | L20: Not Run
A21: AGP-011 | B21: 1. Setup | C21: Agent Profile | D21: Edit | E21: Cancel / navigate away with unsaved profile changes | F21: Agent exists | G21: 1. Click Edit and change Purpose 2. Switch tab or click browser back | H21: - | I21: Either a discard warning, or changes are not saved. Record which. | J21: P3 | K21: Edge | L21: Not Run
A22: AGP-012 | B22: 1. Setup | C22: Agent Profile | D22: Tags | E22: Tag input: Enter adds, duplicates, long tags, many tags | F22: - | G22: 1. Type tag + Enter 2. Add same tag again 3. Add a 100-char tag 4. Add 30 tags | H22: - | I22: Tags added on Enter; duplicate prevented; long/many tags handled without layout break. | J22: P3 | K22: Edge | L22: Not Run
A23: AGP-013 | B23: 1. Setup | C23: Agent Profile | D23: Tabs gating | E23: Identity, Skills, Settings tabs disabled until profile saved | F23: Creating a new Agent | G23: 1. Before clicking Create, hover each other tab | H23: - | I23: Tabs disabled with tooltip 'Available after you save the Agent Profile.' | J23: P2 | K23: Functional | L23: Not Run
A24: AGP-014 | B24: 1. Setup | C24: Agent Profile | D24: ITSM naming | E24: Agent Name must exactly match ITSM application name | F24: ITSM automation configured; ticket references 'Github' | G24: 1. Create Agent named 'GitHub' 2. Raise ITSM ticket for 'Github' | H24: - | I24: Ticket does not route. Check whether the failure is visible anywhere (docs say it fails silently). | J24: P1 | K24: Negative | L24: Not Run | Q24: Silent failure is a UX risk; raise as improvement if nothing is logged.
A25: AGP-015 | B25: 1. Setup | C25: Agent Profile | D25: Audit | E25: Agent creation recorded in Logs | F25: - | G25: 1. Create an Agent 2. Open Logs | H25: - | I25: Log entry with creating user, Agent name/ID, timestamp. | J25: P2 | K25: Functional | L25: Not Run
A26: AGP-016 | B26: 1. Setup | C26: Agent Profile | D26: Double submit | E26: Double-clicking Create does not create duplicate Agents | F26: - | G26: 1. Fill form 2. Double-click Create quickly | H26: - | I26: Exactly one Agent created. | J26: P2 | K26: Edge | L26: Not Run
A27: AGI-001 | B27: 1. Setup | C27: Agent Identity | D27: Manual | E27: Manual mode: valid credentials verify successfully | F27: Agent created; creds verified by manual login | G27: 1. Agent Identity > Manual 2. Enter Username, Password, Login URL 3. Save | H27: Valid service account | I27: Real login attempted; green banner 'Agent Identity successfully verified' with View Body Cam Footage link; status = Valid. | J27: P0 | K27: Functional | L27: Not Run
A28: AGI-002 | B28: 1. Setup | C28: Agent Identity | D28: Manual | E28: Body Cam of identity verification shows the login | F28: Verified identity | G28: 1. Click View Body Cam Footage | H28: - | I28: Recording shows login page, credential entry (password masked), landing page after login. | J28: P1 | K28: Functional | L28: Not Run
A29: AGI-003 | B29: 1. Setup | C29: Agent Identity | D29: Manual | E29: Wrong password | F29: - | G29: 1. Enter wrong password 2. Save | H29: - | I29: Verification fails; status Invalid; clear error; footage shows the login error. | J29: P0 | K29: Negative | L29: Not Run
A30: AGI-004 | B30: 1. Setup | C30: Agent Identity | D30: Manual | E30: Wrong username / non-existent user | F30: - | G30: 1. Enter unknown username 2. Save | H30: - | I30: Status Invalid with clear error. | J30: P1 | K30: Negative | L30: Not Run
A31: AGI-005 | B31: 1. Setup | C31: Agent Identity | D31: Manual | E31: Required fields: Username, Password, Login URL | F31: - | G31: 1. Leave each required field empty in turn 2. Save | H31: - | I31: Save blocked with required-field messages. | J31: P1 | K31: Negative | L31: Not Run
A32: AGI-006 | B32: 1. Setup | C32: Agent Identity | D32: Login URL | E32: Invalid / malformed Login URL | F32: - | G32: 1. Enter each value 2. Save | H32: 'abc', 'htp://x', 'https://', 'https://doesnotexist.invalid' | I32: Format errors caught before save; unreachable host gives a clear failure, not an endless spinner. | J32: P1 | K32: Negative | L32: Not Run
A33: AGI-007 | B33: 1. Setup | C33: Agent Identity | D33: Login URL | E33: Login URL http vs https, trailing slash, query params | F33: - | G33: 1. Try http://, https://, with trailing '/', with '?returnTo=' param | H33: - | I33: All valid forms work; redirects are followed to the login page. | J33: P3 | K33: Edge | L33: Not Run
A34: AGI-008 | B34: 1. Setup | C34: Agent Identity | D34: Login URL | E34: Login URL is not the login page (home page / deep link) | F34: - | G34: 1. Set Login URL to app home page that redirects to login | H34: - | I34: Agent follows redirect and logs in, or fails with a clear message. | J34: P2 | K34: Edge | L34: Not Run
A35: AGI-009 | B35: 1. Setup | C35: Agent Identity | D35: Login variants | E35: Two-step login (username -> Next -> password) | F35: App with split login (e.g., Microsoft, Google-style) | G35: 1. Configure identity 2. Save | H35: - | I35: Agent completes both steps and verifies. | J35: P0 | K35: Edge | L35: Not Run
A36: AGI-010 | B36: 1. Setup | C36: Agent Identity | D36: Login variants | E36: SSO redirect login (IdP page on another domain) | F36: App redirects to Okta/Entra for login | G36: 1. Configure identity 2. Save | H36: - | I36: Agent completes login on IdP domain and returns to app. Check Safe URLs include IdP domain. | J36: P1 | K36: Edge | L36: Not Run
A37: AGI-011 | B37: 1. Setup | C37: Agent Identity | D37: Login variants | E37: Login page with cookie banner / popup over the form | F37: App shows cookie consent on login page | G37: 1. Configure identity 2. Save | H37: - | I37: Agent dismisses banner and logs in. | J37: P2 | K37: Edge | L37: Not Run
A38: AGI-012 | B38: 1. Setup | C38: Agent Identity | D38: Login variants | E38: Login page with 'Remember me', tenant/domain field, or org selector | F38: App requires a third field (tenant / domain / company ID) | G38: 1. Put the extra value in Additional Information JSON 2. Save | H38: {"tenant": "acme"} | I38: Agent fills the extra field (or documents that this isn't supported). | J38: P2 | K38: Edge | L38: Not Run | Q38: Confirm whether Additional Information is used during login or only by redflows.
A39: AGI-013 | B39: 1. Setup | C39: Agent Identity | D39: Login variants | E39: CAPTCHA on login page | F39: App shows CAPTCHA | G39: 1. Configure identity 2. Save | H39: - | I39: Agent fails gracefully with a clear 'CAPTCHA' reason; no endless retries. | J39: P2 | K39: Negative | L39: Not Run
A40: AGI-014 | B40: 1. Setup | C40: Agent Identity | D40: Login variants | E40: Account locked / password expired / forced password change screen | F40: Service account in each state | G40: 1. Save identity for each | H40: - | I40: Status Invalid with a message that reflects the real reason; Agent does not change the password on its own. | J40: P1 | K40: Negative | L40: Not Run
A41: AGI-015 | B41: 1. Setup | C41: Agent Identity | D41: Login variants | E41: Push-MFA or SMS OTP (not TOTP) | F41: App enforces push/SMS MFA | G41: 1. Configure identity 2. Save | H41: - | I41: Clear failure stating unsupported MFA type; no hang. | J41: P2 | K41: Negative | L41: Not Run
A42: AGI-016 | B42: 1. Setup | C42: Agent Identity | D42: TOTP | E42: Valid TOTP seed with 2FA-enabled app | F42: App enforces TOTP | G42: 1. Enter creds + TOTP seed 2. Save | H42: Base32 seed | I42: Agent enters generated code and verifies. | J42: P0 | K42: Functional | L42: Not Run
...

Sheet Test Assets
A1: Asset ID | B1: Type | C1: What to record / prepare | D1: What it tests | E1: Used by test cases | F1: Ready? (Y/N) | G1: File location
A2: VID-01 | B2: Video | C2: Clean Create Account recording, login to confirmation screen, one take, no noise | D2: Baseline for completeness, variables and end-to-end success | E2: GEN-001, GEN-005, GQA-001, GQA-002, GQA-004, GQA-035, GQA-036, GQA-037, GQA-042, GQA-051, GQA-052, GQA-053, GQA-054, GQD-005, GQD-006, GQD-007, GQD-008, GQD-009, GQD-010, GQD-011, UPL-002
A3: VID-02 | B3: Video | C3: Same flow but recording starts after login (on the admin page) | D3: Recording without login | E3: GQA-003
A4: VID-03 | B4: Video | C4: Same flow with a jump-cut: 2 steps edited out of the middle | D4: Missing steps in video | E4: GQA-005, GQA-006
A5: VID-04 | B5: Video | C5: Recorder clicks the wrong menu item, goes back, then continues correctly | D5: Mistakes / undo noise | E5: GQA-008
A6: VID-05 | B6: Video | C6: Recorder switches browser tab mid-flow; an OS notification pops up | D6: Noise from other tabs/apps | E6: GQA-009
A7: VID-06 | B7: Video | C7: Very fast execution: several clicks per second | D7: Dropped or merged steps | E7: GQA-010
A8: VID-07 | B8: Video | C8: Very slow: long idle pauses, slow typing, cursor wandering | D8: Idle time and spurious hovers | E8: GQA-011, GQA-012
A9: VID-08 | B9: Video | C9: Page with two Save buttons (e.g., Profile section Save and Roles section Save); recorder uses the Roles one | D9: Ambiguous buttons | E9: GQA-014, GQA-054
A10: VID-09 | B10: Video | C10: Flow that uses icon-only tiny buttons (pencil, trash, kebab, gear) | D10: Small icon targeting | E10: GQA-016
A11: VID-10 | B11: Video | C11: Dense admin page: big user table, many fields, per-row Edit buttons, nav link and tab with same text | D11: Dense pages and repeated labels | E11: GQA-015, GQA-018, GQA-019, GQA-054
A12: VID-11 | B12: Video | C12: Long form where Save is below the fold (scrolling needed) | D12: Scrolling | E12: GQA-020
A13: VID-12 | B13: Video | C13: Row actions only visible on hover | D13: HOVER generation | E13: GQA-021
... A44: DOC-04 | B44: DOCX | C44: Word SOP with embedded images | D44: DOCX support | E44: GQD-004

Sheet Open Questions
A1: # | B1: Area | C1: Observation | D1: Question / Recommendation | E1: Related TCs | F1: Answer / Owner
A2: 1 | B2: Docs | C2: Optional variables: syntax page says `$var? = EMPTY`, but the Agents page and Example 6.3 give optional variables real defaults (`$role? = "Admin"`). | D2: Which is the canonical form? Are both valid? | E2: PAR-002, PAR-003
A3: 2 | B3: Docs | C3: Example 6.2 uses `IF $new_role EXISTS` but `$new_role` is declared as required. | D3: Should EXISTS on a required variable be flagged? | E3: EDT
A4: 3 | B4: Docs | C4: Extraction Example 7.11.3 uses `Group_name` / `Members`, breaking the snake_case rule. | D4: Fix the example or relax the rule? | E4: EDT
A5: 4 | B5: Docs | C5: Example 7.11.2 contains `synqa.rjf.com:8888`, which looks like a real internal host. | D5: Replace with a placeholder. | E5: -
A6: 5 | B6: Docs | C6: Syntax page says variables live at the bottom of the script; the Playground has a separate Execution Parameters panel. | D6: Add a note explaining the difference. | E6: -
A7: 6 | B7: Docs | C7: `Update Account` is in the Add Skill menu but not in the Account Skills table. | D7: Document Update Account. | E7: SKL-001
A8: 7 | B8: Docs | C8: `UNTIL` loops while the condition is true, the opposite of what the word suggests. | D8: Rename, or make the docs very explicit. | E8: RTP
A9: 8 | B9: Product | C9: Is a successful run required before Publish? | D9: Decide: block, warn, or allow. | E9: PUB-004
A10: 9 | B10: Product | C10: When a description matches two elements (two 'Save' buttons), does the Agent guess or stop? | D10: Define expected behaviour. | E10: RTE-002
A11: 10 | B11: Product | C11: Does the Agent check state before toggling (already-on toggle / already-checked box)? | D11: Define expected behaviour. | E11: RTE-014, RTE-015
A12: 11 | B12: Product | C12: Does the generator flag gaps / low confidence when steps are missing from a video? | D12: Define expected behaviour. | E12: GQA-005
A13: 12 | B13: Product | C13: Are login steps in a recording stripped from STEPS (since Agent Identity handles login)? | D13: Confirm. | E13: GQA-004
... A21: 20 | B21: Product | C21: ITSM name mismatch fails silently. Is anything logged? | D21: Consider a visible warning. | E21: AGP-014
